/home/ppf19/pna_generator/venv/lib/python3.8/site-packages/flask_sqlalchemy/__init__.py:833: FSADeprecationWarning: SQLALCHEMY_TRACK_MODIFICATIONS adds significant overhead and will be disabled by default in the future.  Set it to True or False to suppress this warning.
  warnings.warn(FSADeprecationWarning(
[2020-06-24 12:24:33 +0000] [101464] [INFO] Worker exiting (pid: 101464)
/home/ppf19/pna_generator/venv/lib/python3.8/site-packages/flask_sqlalchemy/__init__.py:833: FSADeprecationWarning: SQLALCHEMY_TRACK_MODIFICATIONS adds significant overhead and will be disabled by default in the future.  Set it to True or False to suppress this warning.
  warnings.warn(FSADeprecationWarning(
[2020-06-24 12:24:33 +0000] [101463] [INFO] Worker exiting (pid: 101463)
/home/ppf19/pna_generator/venv/lib/python3.8/site-packages/flask_sqlalchemy/__init__.py:833: FSADeprecationWarning: SQLALCHEMY_TRACK_MODIFICATIONS adds significant overhead and will be disabled by default in the future.  Set it to True or False to suppress this warning.
  warnings.warn(FSADeprecationWarning(
[2020-06-24 12:24:33 +0000] [101461] [INFO] Worker exiting (pid: 101461)
/home/ppf19/pna_generator/venv/lib/python3.8/site-packages/flask_sqlalchemy/__init__.py:833: FSADeprecationWarning: SQLALCHEMY_TRACK_MODIFICATIONS adds significant overhead and will be disabled by default in the future.  Set it to True or False to suppress this warning.
  warnings.warn(FSADeprecationWarning(
[2020-06-24 12:24:33 +0000] [101462] [INFO] Worker exiting (pid: 101462)
/home/ppf19/pna_generator/venv/lib/python3.8/site-packages/flask_sqlalchemy/__init__.py:833: FSADeprecationWarning: SQLALCHEMY_TRACK_MODIFICATIONS adds significant overhead and will be disabled by default in the future.  Set it to True or False to suppress this warning.
  warnings.warn(FSADeprecationWarning(
[2020-06-24 12:24:33 +0000] [101460] [INFO] Worker exiting (pid: 101460)
[2020-06-24 12:24:33 +0000] [101458] [INFO] Handling signal: term
[2020-06-24 12:24:33 +0000] [101458] [INFO] Shutting down: Master
[2020-06-24 12:24:35 +0000] [102923] [INFO] Starting gunicorn 20.0.4
[2020-06-24 12:24:35 +0000] [102923] [INFO] Listening at: http://127.0.0.1:8000 (102923)
[2020-06-24 12:24:35 +0000] [102923] [INFO] Using worker: sync
[2020-06-24 12:24:35 +0000] [102925] [INFO] Booting worker with pid: 102925
[2020-06-24 12:24:35 +0000] [102926] [INFO] Booting worker with pid: 102926
[2020-06-24 12:24:36 +0000] [102927] [INFO] Booting worker with pid: 102927
[2020-06-24 12:24:36 +0000] [102928] [INFO] Booting worker with pid: 102928
[2020-06-24 12:24:36 +0000] [102929] [INFO] Booting worker with pid: 102929
[2020-06-25 12:00:38 +0000] [102923] [INFO] Handling signal: term
/home/ppf19/pna_generator/venv/lib/python3.8/site-packages/flask_sqlalchemy/__init__.py:833: FSADeprecationWarning: SQLALCHEMY_TRACK_MODIFICATIONS adds significant overhead and will be disabled by default in the future.  Set it to True or False to suppress this warning.
  warnings.warn(FSADeprecationWarning(
[2020-06-25 12:00:38 +0000] [102928] [INFO] Worker exiting (pid: 102928)
/home/ppf19/pna_generator/venv/lib/python3.8/site-packages/flask_sqlalchemy/__init__.py:833: FSADeprecationWarning: SQLALCHEMY_TRACK_MODIFICATIONS adds significant overhead and will be disabled by default in the future.  Set it to True or False to suppress this warning.
  warnings.warn(FSADeprecationWarning(
[2020-06-25 12:00:38 +0000] [102929] [INFO] Worker exiting (pid: 102929)
/home/ppf19/pna_generator/venv/lib/python3.8/site-packages/flask_sqlalchemy/__init__.py:833: FSADeprecationWarning: SQLALCHEMY_TRACK_MODIFICATIONS adds significant overhead and will be disabled by default in the future.  Set it to True or False to suppress this warning.
  warnings.warn(FSADeprecationWarning(
[2020-06-25 12:00:38 +0000] [102926] [INFO] Worker exiting (pid: 102926)
/home/ppf19/pna_generator/venv/lib/python3.8/site-packages/flask_sqlalchemy/__init__.py:833: FSADeprecationWarning: SQLALCHEMY_TRACK_MODIFICATIONS adds significant overhead and will be disabled by default in the future.  Set it to True or False to suppress this warning.
  warnings.warn(FSADeprecationWarning(
[2020-06-25 12:00:38 +0000] [102927] [INFO] Worker exiting (pid: 102927)
/home/ppf19/pna_generator/venv/lib/python3.8/site-packages/flask_sqlalchemy/__init__.py:833: FSADeprecationWarning: SQLALCHEMY_TRACK_MODIFICATIONS adds significant overhead and will be disabled by default in the future.  Set it to True or False to suppress this warning.
  warnings.warn(FSADeprecationWarning(
[2020-06-25 12:00:38 +0000] [102925] [INFO] Worker exiting (pid: 102925)
[2020-06-25 12:00:38 +0000] [102923] [INFO] Shutting down: Master
[2020-06-25 12:00:41 +0000] [181112] [INFO] Starting gunicorn 20.0.4
[2020-06-25 12:00:41 +0000] [181112] [INFO] Listening at: http://127.0.0.1:8000 (181112)
[2020-06-25 12:00:41 +0000] [181112] [INFO] Using worker: sync
[2020-06-25 12:00:41 +0000] [181114] [INFO] Booting worker with pid: 181114
[2020-06-25 12:00:41 +0000] [181115] [INFO] Booting worker with pid: 181115
[2020-06-25 12:00:41 +0000] [181116] [INFO] Booting worker with pid: 181116
[2020-06-25 12:00:41 +0000] [181117] [INFO] Booting worker with pid: 181117
[2020-06-25 12:00:41 +0000] [181118] [INFO] Booting worker with pid: 181118
/home/ppf19/pna_generator/venv/lib/python3.8/site-packages/flask_sqlalchemy/__init__.py:833: FSADeprecationWarning: SQLALCHEMY_TRACK_MODIFICATIONS adds significant overhead and will be disabled by default in the future.  Set it to True or False to suppress this warning.
  warnings.warn(FSADeprecationWarning(
[2020-06-26 08:08:07,500] ERROR in app: Exception on /download/L2hvbWUvcHBmMTkvcG5hX2dlbmVyYXRvci9icm93c2VyX2Rlc2lnbi9wbmFnL3N0YXRpYy9kYXRhL3BuYXNfMjAyMF8wNl8yNl8wN181OF8xOV8zLmZhc3Rh [GET]
Traceback (most recent call last):
  File "/home/ppf19/pna_generator/venv/lib/python3.8/site-packages/flask/app.py", line 2447, in wsgi_app
    response = self.full_dispatch_request()
  File "/home/ppf19/pna_generator/venv/lib/python3.8/site-packages/flask/app.py", line 1952, in full_dispatch_request
    rv = self.handle_user_exception(e)
  File "/home/ppf19/pna_generator/venv/lib/python3.8/site-packages/flask/app.py", line 1821, in handle_user_exception
    reraise(exc_type, exc_value, tb)
  File "/home/ppf19/pna_generator/venv/lib/python3.8/site-packages/flask/_compat.py", line 39, in reraise
    raise value
  File "/home/ppf19/pna_generator/venv/lib/python3.8/site-packages/flask/app.py", line 1950, in full_dispatch_request
    rv = self.dispatch_request()
  File "/home/ppf19/pna_generator/venv/lib/python3.8/site-packages/flask/app.py", line 1936, in dispatch_request
    return self.view_functions[rule.endpoint](**req.view_args)
  File "/home/ppf19/pna_generator/venv/lib/python3.8/site-packages/flask_login/utils.py", line 272, in decorated_view
    return func(*args, **kwargs)
  File "/home/ppf19/pna_generator/browser_design/pnag/routs.py", line 188, in download
    return send_file(path, as_attachment=True)
  File "/home/ppf19/pna_generator/venv/lib/python3.8/site-packages/flask/helpers.py", line 629, in send_file
    file = open(filename, "rb")
FileNotFoundError: [Errno 2] No such file or directory: '/home/ppf19/pna_generator/browser_design/pnag/static/data/pnas_2020_06_26_07_58_19_3.fasta'
[2020-06-26 08:08:17,267] ERROR in app: Exception on /download/L2hvbWUvcHBmMTkvcG5hX2dlbmVyYXRvci9icm93c2VyX2Rlc2lnbi9wbmFnL3N0YXRpYy9kYXRhL3BuYXNfMjAyMF8wNl8yNl8wN181OF8xOV8zLmZhc3Rh [GET]
Traceback (most recent call last):
  File "/home/ppf19/pna_generator/venv/lib/python3.8/site-packages/flask/app.py", line 2447, in wsgi_app
    response = self.full_dispatch_request()
  File "/home/ppf19/pna_generator/venv/lib/python3.8/site-packages/flask/app.py", line 1952, in full_dispatch_request
    rv = self.handle_user_exception(e)
  File "/home/ppf19/pna_generator/venv/lib/python3.8/site-packages/flask/app.py", line 1821, in handle_user_exception
    reraise(exc_type, exc_value, tb)
  File "/home/ppf19/pna_generator/venv/lib/python3.8/site-packages/flask/_compat.py", line 39, in reraise
    raise value
  File "/home/ppf19/pna_generator/venv/lib/python3.8/site-packages/flask/app.py", line 1950, in full_dispatch_request
    rv = self.dispatch_request()
  File "/home/ppf19/pna_generator/venv/lib/python3.8/site-packages/flask/app.py", line 1936, in dispatch_request
    return self.view_functions[rule.endpoint](**req.view_args)
  File "/home/ppf19/pna_generator/venv/lib/python3.8/site-packages/flask_login/utils.py", line 272, in decorated_view
    return func(*args, **kwargs)
  File "/home/ppf19/pna_generator/browser_design/pnag/routs.py", line 188, in download
    return send_file(path, as_attachment=True)
  File "/home/ppf19/pna_generator/venv/lib/python3.8/site-packages/flask/helpers.py", line 629, in send_file
    file = open(filename, "rb")
FileNotFoundError: [Errno 2] No such file or directory: '/home/ppf19/pna_generator/browser_design/pnag/static/data/pnas_2020_06_26_07_58_19_3.fasta'
/home/ppf19/pna_generator/venv/lib/python3.8/site-packages/flask_sqlalchemy/__init__.py:833: FSADeprecationWarning: SQLALCHEMY_TRACK_MODIFICATIONS adds significant overhead and will be disabled by default in the future.  Set it to True or False to suppress this warning.
  warnings.warn(FSADeprecationWarning(
[2020-06-26 08:09:40,015] ERROR in app: Exception on /download/L2hvbWUvcHBmMTkvcG5hX2dlbmVyYXRvci9icm93c2VyX2Rlc2lnbi9wbmFnL3N0YXRpYy9kYXRhL3BuYXNfMjAyMF8wNl8yNl8wOF8wOF8yOV8zLmZhc3Rh [GET]
Traceback (most recent call last):
  File "/home/ppf19/pna_generator/venv/lib/python3.8/site-packages/flask/app.py", line 2447, in wsgi_app
    response = self.full_dispatch_request()
  File "/home/ppf19/pna_generator/venv/lib/python3.8/site-packages/flask/app.py", line 1952, in full_dispatch_request
    rv = self.handle_user_exception(e)
  File "/home/ppf19/pna_generator/venv/lib/python3.8/site-packages/flask/app.py", line 1821, in handle_user_exception
    reraise(exc_type, exc_value, tb)
  File "/home/ppf19/pna_generator/venv/lib/python3.8/site-packages/flask/_compat.py", line 39, in reraise
    raise value
  File "/home/ppf19/pna_generator/venv/lib/python3.8/site-packages/flask/app.py", line 1950, in full_dispatch_request
    rv = self.dispatch_request()
  File "/home/ppf19/pna_generator/venv/lib/python3.8/site-packages/flask/app.py", line 1936, in dispatch_request
    return self.view_functions[rule.endpoint](**req.view_args)
  File "/home/ppf19/pna_generator/venv/lib/python3.8/site-packages/flask_login/utils.py", line 272, in decorated_view
    return func(*args, **kwargs)
  File "/home/ppf19/pna_generator/browser_design/pnag/routs.py", line 188, in download
    return send_file(path, as_attachment=True)
  File "/home/ppf19/pna_generator/venv/lib/python3.8/site-packages/flask/helpers.py", line 629, in send_file
    file = open(filename, "rb")
FileNotFoundError: [Errno 2] No such file or directory: '/home/ppf19/pna_generator/browser_design/pnag/static/data/pnas_2020_06_26_08_08_29_3.fasta'
[2020-06-26 08:14:01,629] ERROR in app: Exception on /download/L2hvbWUvcHBmMTkvcG5hX2dlbmVyYXRvci9icm93c2VyX2Rlc2lnbi9wbmFnL3N0YXRpYy9kYXRhL3BuYXNfMjAyMF8wNl8yNl8wOF8wOF8yOV8zLmZhc3Rh [GET]
Traceback (most recent call last):
  File "/home/ppf19/pna_generator/venv/lib/python3.8/site-packages/flask/app.py", line 2447, in wsgi_app
    response = self.full_dispatch_request()
  File "/home/ppf19/pna_generator/venv/lib/python3.8/site-packages/flask/app.py", line 1952, in full_dispatch_request
    rv = self.handle_user_exception(e)
  File "/home/ppf19/pna_generator/venv/lib/python3.8/site-packages/flask/app.py", line 1821, in handle_user_exception
    reraise(exc_type, exc_value, tb)
  File "/home/ppf19/pna_generator/venv/lib/python3.8/site-packages/flask/_compat.py", line 39, in reraise
    raise value
  File "/home/ppf19/pna_generator/venv/lib/python3.8/site-packages/flask/app.py", line 1950, in full_dispatch_request
    rv = self.dispatch_request()
  File "/home/ppf19/pna_generator/venv/lib/python3.8/site-packages/flask/app.py", line 1936, in dispatch_request
    return self.view_functions[rule.endpoint](**req.view_args)
  File "/home/ppf19/pna_generator/venv/lib/python3.8/site-packages/flask_login/utils.py", line 272, in decorated_view
    return func(*args, **kwargs)
  File "/home/ppf19/pna_generator/browser_design/pnag/routs.py", line 188, in download
    return send_file(path, as_attachment=True)
  File "/home/ppf19/pna_generator/venv/lib/python3.8/site-packages/flask/helpers.py", line 629, in send_file
    file = open(filename, "rb")
FileNotFoundError: [Errno 2] No such file or directory: '/home/ppf19/pna_generator/browser_design/pnag/static/data/pnas_2020_06_26_08_08_29_3.fasta'
/home/ppf19/pna_generator/venv/lib/python3.8/site-packages/flask_sqlalchemy/__init__.py:833: FSADeprecationWarning: SQLALCHEMY_TRACK_MODIFICATIONS adds significant overhead and will be disabled by default in the future.  Set it to True or False to suppress this warning.
  warnings.warn(FSADeprecationWarning(
[2020-06-26 08:14:05,196] ERROR in app: Exception on /download/L2hvbWUvcHBmMTkvcG5hX2dlbmVyYXRvci9icm93c2VyX2Rlc2lnbi9wbmFnL3N0YXRpYy9kYXRhL3BuYXNfMjAyMF8wNl8yNl8wOF8wOF8yOV8zLmZhc3Rh [GET]
Traceback (most recent call last):
  File "/home/ppf19/pna_generator/venv/lib/python3.8/site-packages/flask/app.py", line 2447, in wsgi_app
    response = self.full_dispatch_request()
  File "/home/ppf19/pna_generator/venv/lib/python3.8/site-packages/flask/app.py", line 1952, in full_dispatch_request
    rv = self.handle_user_exception(e)
  File "/home/ppf19/pna_generator/venv/lib/python3.8/site-packages/flask/app.py", line 1821, in handle_user_exception
    reraise(exc_type, exc_value, tb)
  File "/home/ppf19/pna_generator/venv/lib/python3.8/site-packages/flask/_compat.py", line 39, in reraise
    raise value
  File "/home/ppf19/pna_generator/venv/lib/python3.8/site-packages/flask/app.py", line 1950, in full_dispatch_request
    rv = self.dispatch_request()
  File "/home/ppf19/pna_generator/venv/lib/python3.8/site-packages/flask/app.py", line 1936, in dispatch_request
    return self.view_functions[rule.endpoint](**req.view_args)
  File "/home/ppf19/pna_generator/venv/lib/python3.8/site-packages/flask_login/utils.py", line 272, in decorated_view
    return func(*args, **kwargs)
  File "/home/ppf19/pna_generator/browser_design/pnag/routs.py", line 188, in download
    return send_file(path, as_attachment=True)
  File "/home/ppf19/pna_generator/venv/lib/python3.8/site-packages/flask/helpers.py", line 629, in send_file
    file = open(filename, "rb")
FileNotFoundError: [Errno 2] No such file or directory: '/home/ppf19/pna_generator/browser_design/pnag/static/data/pnas_2020_06_26_08_08_29_3.fasta'
[2020-06-26 08:31:54,639] ERROR in app: Exception on /download/L2hvbWUvcHBmMTkvcG5hX2dlbmVyYXRvci9icm93c2VyX2Rlc2lnbi9wbmFnL3N0YXRpYy9kYXRhL3BuYXNfMjAyMF8wNl8yNl8wOF8xNl81Ml8zLmZhc3Rh [GET]
Traceback (most recent call last):
  File "/home/ppf19/pna_generator/venv/lib/python3.8/site-packages/flask/app.py", line 2447, in wsgi_app
    response = self.full_dispatch_request()
  File "/home/ppf19/pna_generator/venv/lib/python3.8/site-packages/flask/app.py", line 1952, in full_dispatch_request
    rv = self.handle_user_exception(e)
  File "/home/ppf19/pna_generator/venv/lib/python3.8/site-packages/flask/app.py", line 1821, in handle_user_exception
    reraise(exc_type, exc_value, tb)
  File "/home/ppf19/pna_generator/venv/lib/python3.8/site-packages/flask/_compat.py", line 39, in reraise
    raise value
  File "/home/ppf19/pna_generator/venv/lib/python3.8/site-packages/flask/app.py", line 1950, in full_dispatch_request
    rv = self.dispatch_request()
  File "/home/ppf19/pna_generator/venv/lib/python3.8/site-packages/flask/app.py", line 1936, in dispatch_request
    return self.view_functions[rule.endpoint](**req.view_args)
  File "/home/ppf19/pna_generator/venv/lib/python3.8/site-packages/flask_login/utils.py", line 272, in decorated_view
    return func(*args, **kwargs)
  File "/home/ppf19/pna_generator/browser_design/pnag/routs.py", line 188, in download
    return send_file(path, as_attachment=True)
  File "/home/ppf19/pna_generator/venv/lib/python3.8/site-packages/flask/helpers.py", line 629, in send_file
    file = open(filename, "rb")
FileNotFoundError: [Errno 2] No such file or directory: '/home/ppf19/pna_generator/browser_design/pnag/static/data/pnas_2020_06_26_08_16_52_3.fasta'
[2020-06-26 10:26:08,758] ERROR in app: Exception on /download/L2hvbWUvcHBmMTkvcG5hX2dlbmVyYXRvci9icm93c2VyX2Rlc2lnbi9wbmFnL3N0YXRpYy9kYXRhL3BuYXNfMjAyMF8wNl8yNl8wOF81MF8yNF8zLmZhc3Rh [GET]
Traceback (most recent call last):
  File "/home/ppf19/pna_generator/venv/lib/python3.8/site-packages/flask/app.py", line 2447, in wsgi_app
    response = self.full_dispatch_request()
  File "/home/ppf19/pna_generator/venv/lib/python3.8/site-packages/flask/app.py", line 1952, in full_dispatch_request
    rv = self.handle_user_exception(e)
  File "/home/ppf19/pna_generator/venv/lib/python3.8/site-packages/flask/app.py", line 1821, in handle_user_exception
    reraise(exc_type, exc_value, tb)
  File "/home/ppf19/pna_generator/venv/lib/python3.8/site-packages/flask/_compat.py", line 39, in reraise
    raise value
  File "/home/ppf19/pna_generator/venv/lib/python3.8/site-packages/flask/app.py", line 1950, in full_dispatch_request
    rv = self.dispatch_request()
  File "/home/ppf19/pna_generator/venv/lib/python3.8/site-packages/flask/app.py", line 1936, in dispatch_request
    return self.view_functions[rule.endpoint](**req.view_args)
  File "/home/ppf19/pna_generator/venv/lib/python3.8/site-packages/flask_login/utils.py", line 272, in decorated_view
    return func(*args, **kwargs)
  File "/home/ppf19/pna_generator/browser_design/pnag/routs.py", line 188, in download
    return send_file(path, as_attachment=True)
  File "/home/ppf19/pna_generator/venv/lib/python3.8/site-packages/flask/helpers.py", line 629, in send_file
    file = open(filename, "rb")
FileNotFoundError: [Errno 2] No such file or directory: '/home/ppf19/pna_generator/browser_design/pnag/static/data/pnas_2020_06_26_08_50_24_3.fasta'
[2020-06-26 13:39:08,292] ERROR in app: Exception on /download/L2hvbWUvcHBmMTkvcG5hX2dlbmVyYXRvci9icm93c2VyX2Rlc2lnbi9wbmFnL3N0YXRpYy9kYXRhL3BuYXNfMjAyMF8wNl8yNl8wN181OF8xOV8zLmZhc3Rh [GET]
Traceback (most recent call last):
  File "/home/ppf19/pna_generator/venv/lib/python3.8/site-packages/flask/app.py", line 2447, in wsgi_app
    response = self.full_dispatch_request()
  File "/home/ppf19/pna_generator/venv/lib/python3.8/site-packages/flask/app.py", line 1952, in full_dispatch_request
    rv = self.handle_user_exception(e)
  File "/home/ppf19/pna_generator/venv/lib/python3.8/site-packages/flask/app.py", line 1821, in handle_user_exception
    reraise(exc_type, exc_value, tb)
  File "/home/ppf19/pna_generator/venv/lib/python3.8/site-packages/flask/_compat.py", line 39, in reraise
    raise value
  File "/home/ppf19/pna_generator/venv/lib/python3.8/site-packages/flask/app.py", line 1950, in full_dispatch_request
    rv = self.dispatch_request()
  File "/home/ppf19/pna_generator/venv/lib/python3.8/site-packages/flask/app.py", line 1936, in dispatch_request
    return self.view_functions[rule.endpoint](**req.view_args)
  File "/home/ppf19/pna_generator/venv/lib/python3.8/site-packages/flask_login/utils.py", line 272, in decorated_view
    return func(*args, **kwargs)
  File "/home/ppf19/pna_generator/browser_design/pnag/routs.py", line 188, in download
    return send_file(path, as_attachment=True)
  File "/home/ppf19/pna_generator/venv/lib/python3.8/site-packages/flask/helpers.py", line 629, in send_file
    file = open(filename, "rb")
FileNotFoundError: [Errno 2] No such file or directory: '/home/ppf19/pna_generator/browser_design/pnag/static/data/pnas_2020_06_26_07_58_19_3.fasta'
/home/ppf19/pna_generator/venv/lib/python3.8/site-packages/flask_sqlalchemy/__init__.py:833: FSADeprecationWarning: SQLALCHEMY_TRACK_MODIFICATIONS adds significant overhead and will be disabled by default in the future.  Set it to True or False to suppress this warning.
  warnings.warn(FSADeprecationWarning(
[2020-06-26 13:39:17,540] ERROR in app: Exception on /download/L2hvbWUvcHBmMTkvcG5hX2dlbmVyYXRvci9icm93c2VyX2Rlc2lnbi9wbmFnL3N0YXRpYy9kYXRhL3BuYXNfMjAyMF8wNl8yNl8wOF8xNl81Ml8zLmZhc3Rh [GET]
Traceback (most recent call last):
  File "/home/ppf19/pna_generator/venv/lib/python3.8/site-packages/flask/app.py", line 2447, in wsgi_app
    response = self.full_dispatch_request()
  File "/home/ppf19/pna_generator/venv/lib/python3.8/site-packages/flask/app.py", line 1952, in full_dispatch_request
    rv = self.handle_user_exception(e)
  File "/home/ppf19/pna_generator/venv/lib/python3.8/site-packages/flask/app.py", line 1821, in handle_user_exception
    reraise(exc_type, exc_value, tb)
  File "/home/ppf19/pna_generator/venv/lib/python3.8/site-packages/flask/_compat.py", line 39, in reraise
    raise value
  File "/home/ppf19/pna_generator/venv/lib/python3.8/site-packages/flask/app.py", line 1950, in full_dispatch_request
    rv = self.dispatch_request()
  File "/home/ppf19/pna_generator/venv/lib/python3.8/site-packages/flask/app.py", line 1936, in dispatch_request
    return self.view_functions[rule.endpoint](**req.view_args)
  File "/home/ppf19/pna_generator/venv/lib/python3.8/site-packages/flask_login/utils.py", line 272, in decorated_view
    return func(*args, **kwargs)
  File "/home/ppf19/pna_generator/browser_design/pnag/routs.py", line 188, in download
    return send_file(path, as_attachment=True)
  File "/home/ppf19/pna_generator/venv/lib/python3.8/site-packages/flask/helpers.py", line 629, in send_file
    file = open(filename, "rb")
FileNotFoundError: [Errno 2] No such file or directory: '/home/ppf19/pna_generator/browser_design/pnag/static/data/pnas_2020_06_26_08_16_52_3.fasta'
[2020-06-29 09:39:26,040] ERROR in app: Exception on /download/L2hvbWUvcHBmMTkvcG5hX2dlbmVyYXRvci9icm93c2VyX2Rlc2lnbi9wbmFnL3N0YXRpYy9kYXRhL3BuYXNfMjAyMF8wNl8yNl8wN181OF8xOV8zLmZhc3Rh [GET]
Traceback (most recent call last):
  File "/home/ppf19/pna_generator/venv/lib/python3.8/site-packages/flask/app.py", line 2447, in wsgi_app
    response = self.full_dispatch_request()
  File "/home/ppf19/pna_generator/venv/lib/python3.8/site-packages/flask/app.py", line 1952, in full_dispatch_request
    rv = self.handle_user_exception(e)
  File "/home/ppf19/pna_generator/venv/lib/python3.8/site-packages/flask/app.py", line 1821, in handle_user_exception
    reraise(exc_type, exc_value, tb)
  File "/home/ppf19/pna_generator/venv/lib/python3.8/site-packages/flask/_compat.py", line 39, in reraise
    raise value
  File "/home/ppf19/pna_generator/venv/lib/python3.8/site-packages/flask/app.py", line 1950, in full_dispatch_request
    rv = self.dispatch_request()
  File "/home/ppf19/pna_generator/venv/lib/python3.8/site-packages/flask/app.py", line 1936, in dispatch_request
    return self.view_functions[rule.endpoint](**req.view_args)
  File "/home/ppf19/pna_generator/venv/lib/python3.8/site-packages/flask_login/utils.py", line 272, in decorated_view
    return func(*args, **kwargs)
  File "/home/ppf19/pna_generator/browser_design/pnag/routs.py", line 188, in download
    return send_file(path, as_attachment=True)
  File "/home/ppf19/pna_generator/venv/lib/python3.8/site-packages/flask/helpers.py", line 629, in send_file
    file = open(filename, "rb")
FileNotFoundError: [Errno 2] No such file or directory: '/home/ppf19/pna_generator/browser_design/pnag/static/data/pnas_2020_06_26_07_58_19_3.fasta'
[2020-06-29 09:39:35,793] ERROR in app: Exception on /delete_result/2 [GET]
Traceback (most recent call last):
  File "/home/ppf19/pna_generator/venv/lib/python3.8/site-packages/flask/app.py", line 2447, in wsgi_app
    response = self.full_dispatch_request()
  File "/home/ppf19/pna_generator/venv/lib/python3.8/site-packages/flask/app.py", line 1952, in full_dispatch_request
    rv = self.handle_user_exception(e)
  File "/home/ppf19/pna_generator/venv/lib/python3.8/site-packages/flask/app.py", line 1821, in handle_user_exception
    reraise(exc_type, exc_value, tb)
  File "/home/ppf19/pna_generator/venv/lib/python3.8/site-packages/flask/_compat.py", line 39, in reraise
    raise value
  File "/home/ppf19/pna_generator/venv/lib/python3.8/site-packages/flask/app.py", line 1950, in full_dispatch_request
    rv = self.dispatch_request()
  File "/home/ppf19/pna_generator/venv/lib/python3.8/site-packages/flask/app.py", line 1936, in dispatch_request
    return self.view_functions[rule.endpoint](**req.view_args)
  File "/home/ppf19/pna_generator/venv/lib/python3.8/site-packages/flask_login/utils.py", line 272, in decorated_view
    return func(*args, **kwargs)
  File "/home/ppf19/pna_generator/browser_design/pnag/routs.py", line 170, in delete_result
    os.remove(res.result)
FileNotFoundError: [Errno 2] No such file or directory: '/home/ppf19/pna_generator/browser_design/pnag/static/data/pnas_2020_06_26_07_58_19_3.fasta'
[2020-06-29 09:40:25,183] ERROR in app: Exception on /delete_result/5 [GET]
Traceback (most recent call last):
  File "/home/ppf19/pna_generator/venv/lib/python3.8/site-packages/flask/app.py", line 2447, in wsgi_app
    response = self.full_dispatch_request()
  File "/home/ppf19/pna_generator/venv/lib/python3.8/site-packages/flask/app.py", line 1952, in full_dispatch_request
    rv = self.handle_user_exception(e)
  File "/home/ppf19/pna_generator/venv/lib/python3.8/site-packages/flask/app.py", line 1821, in handle_user_exception
    reraise(exc_type, exc_value, tb)
  File "/home/ppf19/pna_generator/venv/lib/python3.8/site-packages/flask/_compat.py", line 39, in reraise
    raise value
  File "/home/ppf19/pna_generator/venv/lib/python3.8/site-packages/flask/app.py", line 1950, in full_dispatch_request
    rv = self.dispatch_request()
  File "/home/ppf19/pna_generator/venv/lib/python3.8/site-packages/flask/app.py", line 1936, in dispatch_request
    return self.view_functions[rule.endpoint](**req.view_args)
  File "/home/ppf19/pna_generator/venv/lib/python3.8/site-packages/flask_login/utils.py", line 272, in decorated_view
    return func(*args, **kwargs)
  File "/home/ppf19/pna_generator/browser_design/pnag/routs.py", line 170, in delete_result
    os.remove(res.result)
FileNotFoundError: [Errno 2] No such file or directory: '/home/ppf19/pna_generator/browser_design/pnag/static/data/pnas_2020_06_26_08_50_24_3.fasta'
[2020-06-29 09:40:31,446] ERROR in app: Exception on /delete_result/5 [GET]
Traceback (most recent call last):
  File "/home/ppf19/pna_generator/venv/lib/python3.8/site-packages/flask/app.py", line 2447, in wsgi_app
    response = self.full_dispatch_request()
  File "/home/ppf19/pna_generator/venv/lib/python3.8/site-packages/flask/app.py", line 1952, in full_dispatch_request
    rv = self.handle_user_exception(e)
  File "/home/ppf19/pna_generator/venv/lib/python3.8/site-packages/flask/app.py", line 1821, in handle_user_exception
    reraise(exc_type, exc_value, tb)
  File "/home/ppf19/pna_generator/venv/lib/python3.8/site-packages/flask/_compat.py", line 39, in reraise
    raise value
  File "/home/ppf19/pna_generator/venv/lib/python3.8/site-packages/flask/app.py", line 1950, in full_dispatch_request
    rv = self.dispatch_request()
  File "/home/ppf19/pna_generator/venv/lib/python3.8/site-packages/flask/app.py", line 1936, in dispatch_request
    return self.view_functions[rule.endpoint](**req.view_args)
  File "/home/ppf19/pna_generator/venv/lib/python3.8/site-packages/flask_login/utils.py", line 272, in decorated_view
    return func(*args, **kwargs)
  File "/home/ppf19/pna_generator/browser_design/pnag/routs.py", line 167, in delete_result
    os.remove(res.gff)
FileNotFoundError: [Errno 2] No such file or directory: '/home/ppf19/pna_generator/browser_design/pnag/static/data/gff_2020_06_26_08_50_24_3.gff3'
[2020-06-30 10:50:28 +0000] [181117] [INFO] Worker exiting (pid: 181117)
[2020-06-30 10:50:28 +0000] [181114] [INFO] Worker exiting (pid: 181114)
[2020-06-30 10:50:28 +0000] [181115] [INFO] Worker exiting (pid: 181115)
[2020-06-30 10:50:28 +0000] [181116] [INFO] Worker exiting (pid: 181116)
[2020-06-30 10:50:28 +0000] [181112] [INFO] Handling signal: term
/home/ppf19/pna_generator/venv/lib/python3.8/site-packages/flask_sqlalchemy/__init__.py:833: FSADeprecationWarning: SQLALCHEMY_TRACK_MODIFICATIONS adds significant overhead and will be disabled by default in the future.  Set it to True or False to suppress this warning.
  warnings.warn(FSADeprecationWarning(
[2020-06-30 10:50:28 +0000] [181118] [INFO] Worker exiting (pid: 181118)
[2020-06-30 10:50:29 +0000] [181112] [INFO] Shutting down: Master
[2020-06-30 10:50:33 +0000] [586536] [INFO] Starting gunicorn 20.0.4
[2020-06-30 10:50:33 +0000] [586536] [INFO] Listening at: http://127.0.0.1:8000 (586536)
[2020-06-30 10:50:33 +0000] [586536] [INFO] Using worker: sync
[2020-06-30 10:50:33 +0000] [586538] [INFO] Booting worker with pid: 586538
[2020-06-30 10:50:33 +0000] [586539] [INFO] Booting worker with pid: 586539
[2020-06-30 10:50:33 +0000] [586540] [INFO] Booting worker with pid: 586540
[2020-06-30 10:50:33 +0000] [586541] [INFO] Booting worker with pid: 586541
[2020-06-30 10:50:33 +0000] [586542] [INFO] Booting worker with pid: 586542
/home/ppf19/pna_generator/venv/lib/python3.8/site-packages/flask_sqlalchemy/__init__.py:833: FSADeprecationWarning: SQLALCHEMY_TRACK_MODIFICATIONS adds significant overhead and will be disabled by default in the future.  Set it to True or False to suppress this warning.
  warnings.warn(FSADeprecationWarning(
[2020-06-30 10:50:37,387] ERROR in app: Exception on /start [POST]
Traceback (most recent call last):
  File "/home/ppf19/pna_generator/venv/lib/python3.8/site-packages/werkzeug/datastructures.py", line 3089, in __getattr__
    return getattr(self.stream, name)
AttributeError: 'SpooledTemporaryFile' object has no attribute 'find'

During handling of the above exception, another exception occurred:

Traceback (most recent call last):
  File "/home/ppf19/pna_generator/venv/lib/python3.8/site-packages/flask/app.py", line 2447, in wsgi_app
    response = self.full_dispatch_request()
  File "/home/ppf19/pna_generator/venv/lib/python3.8/site-packages/flask/app.py", line 1952, in full_dispatch_request
    rv = self.handle_user_exception(e)
  File "/home/ppf19/pna_generator/venv/lib/python3.8/site-packages/flask/app.py", line 1821, in handle_user_exception
    reraise(exc_type, exc_value, tb)
  File "/home/ppf19/pna_generator/venv/lib/python3.8/site-packages/flask/_compat.py", line 39, in reraise
    raise value
  File "/home/ppf19/pna_generator/venv/lib/python3.8/site-packages/flask/app.py", line 1950, in full_dispatch_request
    rv = self.dispatch_request()
  File "/home/ppf19/pna_generator/venv/lib/python3.8/site-packages/flask/app.py", line 1936, in dispatch_request
    return self.view_functions[rule.endpoint](**req.view_args)
  File "/home/ppf19/pna_generator/venv/lib/python3.8/site-packages/flask_login/utils.py", line 272, in decorated_view
    return func(*args, **kwargs)
  File "/home/ppf19/pna_generator/browser_design/pnag/routs.py", line 108, in start
    if form.validate_on_submit():
  File "/home/ppf19/pna_generator/venv/lib/python3.8/site-packages/flask_wtf/form.py", line 100, in validate_on_submit
    return self.is_submitted() and self.validate()
  File "/home/ppf19/pna_generator/venv/lib/python3.8/site-packages/wtforms/form.py", line 318, in validate
    return super(Form, self).validate(extra)
  File "/home/ppf19/pna_generator/venv/lib/python3.8/site-packages/wtforms/form.py", line 150, in validate
    if not field.validate(self, extra):
  File "/home/ppf19/pna_generator/venv/lib/python3.8/site-packages/wtforms/fields/core.py", line 226, in validate
    stop_validation = self._run_validation_chain(form, chain)
  File "/home/ppf19/pna_generator/venv/lib/python3.8/site-packages/wtforms/fields/core.py", line 246, in _run_validation_chain
    validator(form, self)
  File "/home/ppf19/pna_generator/browser_design/pnag/forms.py", line 75, in validate_genes
    if genes.data.find('>') != -1:
  File "/home/ppf19/pna_generator/venv/lib/python3.8/site-packages/werkzeug/datastructures.py", line 3095, in __getattr__
    return getattr(self.stream._file, name)
AttributeError: '_io.BytesIO' object has no attribute 'find'
/home/ppf19/pna_generator/venv/lib/python3.8/site-packages/flask_sqlalchemy/__init__.py:833: FSADeprecationWarning: SQLALCHEMY_TRACK_MODIFICATIONS adds significant overhead and will be disabled by default in the future.  Set it to True or False to suppress this warning.
  warnings.warn(FSADeprecationWarning(
[2020-06-30 13:07:37 +0000] [586541] [INFO] Worker exiting (pid: 586541)
/home/ppf19/pna_generator/venv/lib/python3.8/site-packages/flask_sqlalchemy/__init__.py:833: FSADeprecationWarning: SQLALCHEMY_TRACK_MODIFICATIONS adds significant overhead and will be disabled by default in the future.  Set it to True or False to suppress this warning.
  warnings.warn(FSADeprecationWarning(
[2020-06-30 13:07:37 +0000] [586540] [INFO] Worker exiting (pid: 586540)
[2020-06-30 13:07:37 +0000] [586536] [INFO] Handling signal: term
/home/ppf19/pna_generator/venv/lib/python3.8/site-packages/flask_sqlalchemy/__init__.py:833: FSADeprecationWarning: SQLALCHEMY_TRACK_MODIFICATIONS adds significant overhead and will be disabled by default in the future.  Set it to True or False to suppress this warning.
  warnings.warn(FSADeprecationWarning(
[2020-06-30 13:07:37 +0000] [586539] [INFO] Worker exiting (pid: 586539)
[2020-06-30 13:07:37 +0000] [586542] [INFO] Worker exiting (pid: 586542)
/home/ppf19/pna_generator/venv/lib/python3.8/site-packages/flask_sqlalchemy/__init__.py:833: FSADeprecationWarning: SQLALCHEMY_TRACK_MODIFICATIONS adds significant overhead and will be disabled by default in the future.  Set it to True or False to suppress this warning.
  warnings.warn(FSADeprecationWarning(
[2020-06-30 13:07:37 +0000] [586538] [INFO] Worker exiting (pid: 586538)
[2020-06-30 13:07:37 +0000] [586536] [INFO] Shutting down: Master
[2020-06-30 13:07:40 +0000] [594563] [INFO] Starting gunicorn 20.0.4
[2020-06-30 13:07:40 +0000] [594563] [INFO] Listening at: http://127.0.0.1:8000 (594563)
[2020-06-30 13:07:40 +0000] [594563] [INFO] Using worker: sync
[2020-06-30 13:07:40 +0000] [594565] [INFO] Booting worker with pid: 594565
[2020-06-30 13:07:40 +0000] [594566] [INFO] Booting worker with pid: 594566
[2020-06-30 13:07:40 +0000] [594567] [INFO] Booting worker with pid: 594567
[2020-06-30 13:07:40 +0000] [594568] [INFO] Booting worker with pid: 594568
[2020-06-30 13:07:40 +0000] [594569] [INFO] Booting worker with pid: 594569
/home/ppf19/pna_generator/venv/lib/python3.8/site-packages/flask_sqlalchemy/__init__.py:833: FSADeprecationWarning: SQLALCHEMY_TRACK_MODIFICATIONS adds significant overhead and will be disabled by default in the future.  Set it to True or False to suppress this warning.
  warnings.warn(FSADeprecationWarning(
[2020-07-01 10:41:01 +0000] [594566] [INFO] Worker exiting (pid: 594566)
/home/ppf19/pna_generator/venv/lib/python3.8/site-packages/flask_sqlalchemy/__init__.py:833: FSADeprecationWarning: SQLALCHEMY_TRACK_MODIFICATIONS adds significant overhead and will be disabled by default in the future.  Set it to True or False to suppress this warning.
  warnings.warn(FSADeprecationWarning(
[2020-07-01 10:41:01 +0000] [594569] [INFO] Worker exiting (pid: 594569)
/home/ppf19/pna_generator/venv/lib/python3.8/site-packages/flask_sqlalchemy/__init__.py:833: FSADeprecationWarning: SQLALCHEMY_TRACK_MODIFICATIONS adds significant overhead and will be disabled by default in the future.  Set it to True or False to suppress this warning.
  warnings.warn(FSADeprecationWarning(
[2020-07-01 10:41:01 +0000] [594568] [INFO] Worker exiting (pid: 594568)
/home/ppf19/pna_generator/venv/lib/python3.8/site-packages/flask_sqlalchemy/__init__.py:833: FSADeprecationWarning: SQLALCHEMY_TRACK_MODIFICATIONS adds significant overhead and will be disabled by default in the future.  Set it to True or False to suppress this warning.
  warnings.warn(FSADeprecationWarning(
[2020-07-01 10:41:01 +0000] [594565] [INFO] Worker exiting (pid: 594565)
/home/ppf19/pna_generator/venv/lib/python3.8/site-packages/flask_sqlalchemy/__init__.py:833: FSADeprecationWarning: SQLALCHEMY_TRACK_MODIFICATIONS adds significant overhead and will be disabled by default in the future.  Set it to True or False to suppress this warning.
  warnings.warn(FSADeprecationWarning(
[2020-07-01 10:41:01 +0000] [594567] [INFO] Worker exiting (pid: 594567)
[2020-07-01 10:41:01 +0000] [594563] [INFO] Handling signal: term
[2020-07-01 10:41:01 +0000] [594563] [INFO] Shutting down: Master
[2020-07-01 10:41:02 +0000] [668850] [INFO] Starting gunicorn 20.0.4
[2020-07-01 10:41:02 +0000] [668850] [INFO] Listening at: http://127.0.0.1:8000 (668850)
[2020-07-01 10:41:02 +0000] [668850] [INFO] Using worker: sync
[2020-07-01 10:41:02 +0000] [668852] [INFO] Booting worker with pid: 668852
[2020-07-01 10:41:02 +0000] [668853] [INFO] Booting worker with pid: 668853
[2020-07-01 10:41:02 +0000] [668854] [INFO] Booting worker with pid: 668854
[2020-07-01 10:41:02 +0000] [668855] [INFO] Booting worker with pid: 668855
[2020-07-01 10:41:02 +0000] [668856] [INFO] Booting worker with pid: 668856
